

```javascript function test(){
   try{
       setTimeout(()=>{
           console.log(1)
            throw new Error('hello')
       },1000)
       console.log(2)
       throw new Error('world')
       console.log(3)
       return 
   }catch(err){
       console.log(err)
   }finally{
       console.log(4)
   }
}

test()
```
### 运行可知,setimeout 中的错误不会被捕捉,因为它的回调函数和test函数不在同一个作用域中.
### 另外finally 除了前面有死循环以外,是无论如何都会在最后执行的,不管中间有多少错误,代码或者被return;
